testFileList (actionsapitests.ActionsAPITestCase) ... [35mDestination directory /Volumes/Centauri/Users/malfunct/Code/projects/pisi/tmp does not exist. Creating it.
[0m[35mWriting current database version for dbversion
[0m[35mWriting current database version for filesdbversion
[0mok
testShelltoolsCanAccessDir (actionsapitests.ActionsAPITestCase) ... ok
testShelltoolsCanAccessFile (actionsapitests.ActionsAPITestCase) ... ok
testShelltoolsCopy (actionsapitests.ActionsAPITestCase) ... ok
testShelltoolsEcho (actionsapitests.ActionsAPITestCase) ... ok
testShelltoolsMakedirs (actionsapitests.ActionsAPITestCase) ... ok
testShelltoolsSystem (actionsapitests.ActionsAPITestCase) ... ok

----------------------------------------------------------------------
Ran 7 tests in 10.638s

OK
testMakeZip (archivetests.ArchiveFileTestCase) ... ok
testUnpackTar (archivetests.ArchiveFileTestCase) ... ok
testUnpackZip (archivetests.ArchiveFileTestCase) ... ok
testUnpackZipCond (archivetests.ArchiveFileTestCase) ... ok

----------------------------------------------------------------------
Ran 4 tests in 13.249s

OK
testDeclaration (autoxmltests.AutoXmlTestCase) ... ok
testReadWrite (autoxmltests.AutoXmlTestCase) ... ERROR
testWriteRead (autoxmltests.AutoXmlTestCase) ... ok
testStr (autoxmltests.LocalTextTestCase) ... ok

======================================================================
ERROR: testReadWrite (autoxmltests.AutoXmlTestCase)
----------------------------------------------------------------------
Traceback (most recent call last):
  File "/Volumes/Centauri/Users/malfunct/Code/projects/pisi/tests/autoxmltests.py", line 70, in testReadWrite
    a.write('/tmp/a.xml')
  File "./pisi/pxml/autoxml.py", line 452, in write
    self.encode(self.rootNode(), errs)
  File "./pisi/pxml/autoxml.py", line 356, in encode
    encode_member(self, node, errs)
  File "./pisi/pxml/autoxml.py", line 544, in encode
    encode_a(node, value, errs)
  File "./pisi/pxml/autoxml.py", line 643, in encode
    writetext(node, token, unicode(value))
  File "./pisi/pxml/autoxml.py", line 518, in writetext
    addText(node, "", text)
  File "./pisi/pxml/xmlextpiks.py", line 169, in addText
    node.insertData(text)
UnicodeEncodeError: 'ascii' codec can't encode character u'\u0131' in position 1: ordinal not in range(128)

----------------------------------------------------------------------
Ran 4 tests in 0.009s

FAILED (errors=1)
testBasicBuild (buildtests.BuildTestCase) ... ** Running all tests

* Running tests in actionsapitests.py

* Running tests in archivetests.py

* Running tests in autoxmltests.py

* Running tests in buildtests.py
[35mBuilding PISI source package: a
[0m[35mSafety switch: the component system.devel cannot be found
[0mFetching source from: http://cekirdek.uludag.org.tr/~meren/merhaba-pisi-1.0.tar.gz
ERROR
testBuildNumber (buildtests.BuildTestCase) ... [35mBuilding PISI source package: a
[0m[35mSafety switch: the component system.devel cannot be found
[0mFetching source from: http://cekirdek.uludag.org.tr/~meren/merhaba-pisi-1.0.tar.gz
ERROR

======================================================================
ERROR: testBasicBuild (buildtests.BuildTestCase)
----------------------------------------------------------------------
Traceback (most recent call last):
  File "/Volumes/Centauri/Users/malfunct/Code/projects/pisi/tests/buildtests.py", line 39, in testBasicBuild
    pb.build()
  File "./pisi/build.py", line 194, in build
    self.fetch_source_archive()
  File "./pisi/build.py", line 308, in fetch_source_archive
    self.sourceArchive.fetch()
  File "./pisi/sourcearchive.py", line 50, in fetch
    fetch_url(self.url, ctx.config.archives_dir(), progress)
  File "./pisi/fetcher.py", line 55, in fetch_url
    fetch.fetch()
  File "./pisi/fetcher.py", line 100, in fetch
    self.fetchRemoteFile(partial_file)
  File "./pisi/fetcher.py", line 198, in fetchRemoteFile
    self.err(_('Cannot fetch %s; %s') % (uri, e[-1][-1]))
  File "./pisi/fetcher.py", line 253, in err
    raise FetchError(error)
FetchError: Cannot fetch http://cekirdek.uludag.org.tr/~meren/merhaba-pisi-1.0.tar.gz; nodename nor servname provided, or not known

======================================================================
ERROR: testBuildNumber (buildtests.BuildTestCase)
----------------------------------------------------------------------
Traceback (most recent call last):
  File "/Volumes/Centauri/Users/malfunct/Code/projects/pisi/tests/buildtests.py", line 44, in testBuildNumber
    self.testBasicBuild()
  File "/Volumes/Centauri/Users/malfunct/Code/projects/pisi/tests/buildtests.py", line 39, in testBasicBuild
    pb.build()
  File "./pisi/build.py", line 194, in build
    self.fetch_source_archive()
  File "./pisi/build.py", line 308, in fetch_source_archive
    self.sourceArchive.fetch()
  File "./pisi/sourcearchive.py", line 50, in fetch
    fetch_url(self.url, ctx.config.archives_dir(), progress)
  File "./pisi/fetcher.py", line 55, in fetch_url
    fetch.fetch()
  File "./pisi/fetcher.py", line 100, in fetch
    self.fetchRemoteFile(partial_file)
  File "./pisi/fetcher.py", line 198, in fetchRemoteFile
    self.err(_('Cannot fetch %s; %s') % (uri, e[-1][-1]))
  File "./pisi/fetcher.py", line 253, in err
    raise FetchError(error)
FetchError: Cannot fetch http://cekirdek.uludag.org.tr/~meren/merhaba-pisi-1.0.tar.gz; nodename nor servname provided, or not known

----------------------------------------------------------------------
Ran 2 tests in 0.866s

FAILED (errors=2)
testAccessMethods (configfiletests.ConfigFileTestCase) ... ok
testFlagsExists (configfiletests.ConfigFileTestCase) ... ok
testSections (configfiletests.ConfigFileTestCase) ... ok
testValues (configfiletests.ConfigFileTestCase) ... ok

----------------------------------------------------------------------
Ran 4 tests in 0.002s

OK
testConflictWithEachOther (conflicttests.ConflictTestCase) ... ok
testConflictWithEachOtherAndInstalled (conflicttests.ConflictTestCase) ... ok
testConflictWithInstalled (conflicttests.ConflictTestCase) ... ok

----------------------------------------------------------------------
Ran 3 tests in 3.397s

OK
testConstValues (constantstests.ContextTestCase) ... ok
testConstness (constantstests.ContextTestCase) ... ok

----------------------------------------------------------------------
Ran 2 tests in 0.000s

OK
testReleaseFrom (dependencytests.DependencyTestCase) ... ok
testReleaseIs (dependencytests.DependencyTestCase) ... ok
testReleaseTo (dependencytests.DependencyTestCase) ... ok
testVersionFrom (dependencytests.DependencyTestCase) ... ok

----------------------------------------------------------------------
Ran 4 tests in 0.001s

OK
testFetch (fetchertests.FetcherTestCase) ... ERROR
testResume (fetchertests.FetcherTestCase) ... ERROR

======================================================================
ERROR: testFetch (fetchertests.FetcherTestCase)
----------------------------------------------------------------------
Traceback (most recent call last):
  File "/Volumes/Centauri/Users/malfunct/Code/projects/pisi/tests/fetchertests.py", line 35, in testFetch
    self.fetch.fetch()
  File "./pisi/fetcher.py", line 100, in fetch
    self.fetchRemoteFile(partial_file)
  File "./pisi/fetcher.py", line 198, in fetchRemoteFile
    self.err(_('Cannot fetch %s; %s') % (uri, e[-1][-1]))
  File "./pisi/fetcher.py", line 253, in err
    raise FetchError(error)
FetchError: Cannot fetch http://cekirdek.uludag.org.tr/~eray/hello-1.3.tar.gz; nodename nor servname provided, or not known

======================================================================
ERROR: testResume (fetchertests.FetcherTestCase)
----------------------------------------------------------------------
Traceback (most recent call last):
  File "/Volumes/Centauri/Users/malfunct/Code/projects/pisi/tests/fetchertests.py", line 45, in testResume
    self.fetch.fetch()
  File "./pisi/fetcher.py", line 100, in fetch
    self.fetchRemoteFile(partial_file)
  File "./pisi/fetcher.py", line 198, in fetchRemoteFile
    self.err(_('Cannot fetch %s; %s') % (uri, e[-1][-1]))
  File "./pisi/fetcher.py", line 253, in err
    raise FetchError(error)
FetchError: Cannot fetch http://cekirdek.uludag.org.tr/~eray/hello-1.3.tar.gz; nodename nor servname provided, or not known

----------------------------------------------------------------------
Ran 2 tests in 0.007s

FAILED (errors=2)
testFileInfo (filestests.FilesTestCase) ... ok

----------------------------------------------------------------------
Ran 1 test in 0.001s

OK
testLocalFile (filetests.FileTestCase) ... ok
testRemoteRead (filetests.FileTestCase) ... ERROR

======================================================================
ERROR: testRemoteRead (filetests.FileTestCase)
----------------------------------------------------------------------
Traceback (most recent call last):
  File "/Volumes/Centauri/Users/malfunct/Code/projects/pisi/tests/filetests.py", line 30, in testRemoteRead
    f = File("http://uludag.org.tr/haberler/rootfs0.2.html", File.read)
  File "./pisi/file.py", line 160, in __init__
    localfile = File.download(uri, transfer_dir, sha1sum, compress, sign)
  File "./pisi/file.py", line 119, in download
    fetch_url(uri, transfer_dir, ctx.ui.Progress)
  File "./pisi/fetcher.py", line 55, in fetch_url
    fetch.fetch()
  File "./pisi/fetcher.py", line 100, in fetch
    self.fetchRemoteFile(partial_file)
  File "./pisi/fetcher.py", line 198, in fetchRemoteFile
    self.err(_('Cannot fetch %s; %s') % (uri, e[-1][-1]))
  File "./pisi/fetcher.py", line 253, in err
    raise FetchError(error)
FetchError: Cannot fetch http://uludag.org.tr/haberler/rootfs0.2.html; nodename nor servname provided, or not known

----------------------------------------------------------------------
Ran 2 tests in 0.007s

FAILED (errors=1)
testCycle (graphtests.GraphTestCase) ... ok
testTopologicalSort (graphtests.GraphTestCase) ... ok

----------------------------------------------------------------------
Ran 2 tests in 0.000s

OK
testInstall (installdbtests.InstallDBTestCase) ... ok
testRemoveDummy (installdbtests.InstallDBTestCase) ... ok
testRemovePurge (installdbtests.InstallDBTestCase) ... ok

----------------------------------------------------------------------
Ran 3 tests in 3.159s

OK
testRead (metadatatests.MetaDataTestCase) ... ok
testVerify (metadatatests.MetaDataTestCase) ... ok
testWrite (metadatatests.MetaDataTestCase) ... ERROR

======================================================================
ERROR: testWrite (metadatatests.MetaDataTestCase)
----------------------------------------------------------------------
Traceback (most recent call last):
  File "/Volumes/Centauri/Users/malfunct/Code/projects/pisi/tests/metadatatests.py", line 33, in testWrite
    md.write('/tmp/metadata-test.xml')
  File "./pisi/pxml/autoxml.py", line 452, in write
    self.encode(self.rootNode(), errs)
  File "./pisi/pxml/autoxml.py", line 356, in encode
    encode_member(self, node, errs)
  File "./pisi/pxml/autoxml.py", line 544, in encode
    encode_a(node, value, errs)
  File "./pisi/pxml/autoxml.py", line 692, in encode
    obj.encode(classnode, errs)
  File "./pisi/pxml/autoxml.py", line 356, in encode
    encode_member(self, node, errs)
  File "./pisi/pxml/autoxml.py", line 544, in encode
    encode_a(node, value, errs)
  File "./pisi/pxml/autoxml.py", line 692, in encode
    obj.encode(classnode, errs)
  File "./pisi/pxml/autoxml.py", line 356, in encode
    encode_member(self, node, errs)
  File "./pisi/pxml/autoxml.py", line 544, in encode
    encode_a(node, value, errs)
  File "./pisi/pxml/autoxml.py", line 643, in encode
    writetext(node, token, unicode(value))
  File "./pisi/pxml/autoxml.py", line 497, in writetext
    addText(node, tagpath, text)
  File "./pisi/pxml/xmlextpiks.py", line 169, in addText
    node.insertData(text)
UnicodeEncodeError: 'ascii' codec can't encode character u'\u0131' in position 1: ordinal not in range(128)

----------------------------------------------------------------------
Ran 3 tests in 0.005s

FAILED (errors=1)
testautosuper (ootests.OOTestCase) ... ok

----------------------------------------------------------------------
Ran 1 test in 0.000s

OK
testAdd (packagedbtests.PackageDBTestCase) ... 

******ERROR: HANGED******