testFileList (actionsapitests.ActionsAPITestCase) ... ok
testShelltoolsCanAccessDir (actionsapitests.ActionsAPITestCase) ... ok
testShelltoolsCanAccessFile (actionsapitests.ActionsAPITestCase) ... ok
testShelltoolsCopy (actionsapitests.ActionsAPITestCase) ... ok
testShelltoolsEcho (actionsapitests.ActionsAPITestCase) ... ok
testShelltoolsMakedirs (actionsapitests.ActionsAPITestCase) ... ok
testShelltoolsSystem (actionsapitests.ActionsAPITestCase) ... ok

----------------------------------------------------------------------
Ran 7 tests in 4.388s

OK
testMakeZip (archivetests.ArchiveFileTestCase) ... ok
testUnpackTar (archivetests.ArchiveFileTestCase) ... ok
testUnpackZip (archivetests.ArchiveFileTestCase) ... ok
testUnpackZipCond (archivetests.ArchiveFileTestCase) ... ok

----------------------------------------------------------------------
Ran 4 tests in 3.753s

OK
testDeclaration (autoxmltests.AutoXmlTestCase) ... ok
testReadWrite (autoxmltests.AutoXmlTestCase) ... ok
testWriteRead (autoxmltests.AutoXmlTestCase) ... ok
testStr (autoxmltests.LocalTextTestCase) ... ok

----------------------------------------------------------------------
Ran 4 tests in 0.009s

OK
testBasicBuild (buildtests.BuildTestCase) ... ** Running all tests

* Running tests in actionsapitests.py

* Running tests in archivetests.py

* Running tests in autoxmltests.py

* Running tests in buildtests.py
[35mBuilding PISI source package: a
[0m[35mSafety switch: the component system.devel cannot be found
[0mFetching source from: http://cekirdek.uludag.org.tr/~meren/merhaba-pisi-1.0.tar.gz
ERROR
testBuildNumber (buildtests.BuildTestCase) ... [35mBuilding PISI source package: a
[0m[35mSafety switch: the component system.devel cannot be found
[0mFetching source from: http://cekirdek.uludag.org.tr/~meren/merhaba-pisi-1.0.tar.gz
ERROR

======================================================================
ERROR: testBasicBuild (buildtests.BuildTestCase)
----------------------------------------------------------------------
Traceback (most recent call last):
  File "/Volumes/Centauri/Users/malfunct/Code/projects/pisi/tests/buildtests.py", line 39, in testBasicBuild
    pb.build()
  File "./pisi/build.py", line 194, in build
    self.fetch_source_archive()
  File "./pisi/build.py", line 308, in fetch_source_archive
    self.sourceArchive.fetch()
  File "./pisi/sourcearchive.py", line 50, in fetch
    fetch_url(self.url, ctx.config.archives_dir(), progress)
  File "./pisi/fetcher.py", line 55, in fetch_url
    fetch.fetch()
  File "./pisi/fetcher.py", line 100, in fetch
    self.fetchRemoteFile(partial_file)
  File "./pisi/fetcher.py", line 198, in fetchRemoteFile
    self.err(_('Cannot fetch %s; %s') % (uri, e[-1][-1]))
  File "./pisi/fetcher.py", line 253, in err
    raise FetchError(error)
FetchError: Cannot fetch http://cekirdek.uludag.org.tr/~meren/merhaba-pisi-1.0.tar.gz; nodename nor servname provided, or not known

======================================================================
ERROR: testBuildNumber (buildtests.BuildTestCase)
----------------------------------------------------------------------
Traceback (most recent call last):
  File "/Volumes/Centauri/Users/malfunct/Code/projects/pisi/tests/buildtests.py", line 44, in testBuildNumber
    self.testBasicBuild()
  File "/Volumes/Centauri/Users/malfunct/Code/projects/pisi/tests/buildtests.py", line 39, in testBasicBuild
    pb.build()
  File "./pisi/build.py", line 194, in build
    self.fetch_source_archive()
  File "./pisi/build.py", line 308, in fetch_source_archive
    self.sourceArchive.fetch()
  File "./pisi/sourcearchive.py", line 50, in fetch
    fetch_url(self.url, ctx.config.archives_dir(), progress)
  File "./pisi/fetcher.py", line 55, in fetch_url
    fetch.fetch()
  File "./pisi/fetcher.py", line 100, in fetch
    self.fetchRemoteFile(partial_file)
  File "./pisi/fetcher.py", line 198, in fetchRemoteFile
    self.err(_('Cannot fetch %s; %s') % (uri, e[-1][-1]))
  File "./pisi/fetcher.py", line 253, in err
    raise FetchError(error)
FetchError: Cannot fetch http://cekirdek.uludag.org.tr/~meren/merhaba-pisi-1.0.tar.gz; nodename nor servname provided, or not known

----------------------------------------------------------------------
Ran 2 tests in 1.182s

FAILED (errors=2)
testAccessMethods (configfiletests.ConfigFileTestCase) ... ok
testFlagsExists (configfiletests.ConfigFileTestCase) ... ok
testSections (configfiletests.ConfigFileTestCase) ... ok
testValues (configfiletests.ConfigFileTestCase) ... ok

----------------------------------------------------------------------
Ran 4 tests in 0.001s

OK
testConflictWithEachOther (conflicttests.ConflictTestCase) ... ok
testConflictWithEachOtherAndInstalled (conflicttests.ConflictTestCase) ... ok
testConflictWithInstalled (conflicttests.ConflictTestCase) ... ok

----------------------------------------------------------------------
Ran 3 tests in 4.204s

OK
testConstValues (constantstests.ContextTestCase) ... ok
testConstness (constantstests.ContextTestCase) ... ok

----------------------------------------------------------------------
Ran 2 tests in 0.000s

OK
testReleaseFrom (dependencytests.DependencyTestCase) ... ok
testReleaseIs (dependencytests.DependencyTestCase) ... ok
testReleaseTo (dependencytests.DependencyTestCase) ... ok
testVersionFrom (dependencytests.DependencyTestCase) ... ok

----------------------------------------------------------------------
Ran 4 tests in 0.001s

OK
testFetch (fetchertests.FetcherTestCase) ... ERROR
testResume (fetchertests.FetcherTestCase) ... ERROR

======================================================================
ERROR: testFetch (fetchertests.FetcherTestCase)
----------------------------------------------------------------------
Traceback (most recent call last):
  File "/Volumes/Centauri/Users/malfunct/Code/projects/pisi/tests/fetchertests.py", line 35, in testFetch
    self.fetch.fetch()
  File "./pisi/fetcher.py", line 100, in fetch
    self.fetchRemoteFile(partial_file)
  File "./pisi/fetcher.py", line 198, in fetchRemoteFile
    self.err(_('Cannot fetch %s; %s') % (uri, e[-1][-1]))
  File "./pisi/fetcher.py", line 253, in err
    raise FetchError(error)
FetchError: Cannot fetch http://cekirdek.uludag.org.tr/~eray/hello-1.3.tar.gz; nodename nor servname provided, or not known

======================================================================
ERROR: testResume (fetchertests.FetcherTestCase)
----------------------------------------------------------------------
Traceback (most recent call last):
  File "/Volumes/Centauri/Users/malfunct/Code/projects/pisi/tests/fetchertests.py", line 45, in testResume
    self.fetch.fetch()
  File "./pisi/fetcher.py", line 100, in fetch
    self.fetchRemoteFile(partial_file)
  File "./pisi/fetcher.py", line 198, in fetchRemoteFile
    self.err(_('Cannot fetch %s; %s') % (uri, e[-1][-1]))
  File "./pisi/fetcher.py", line 253, in err
    raise FetchError(error)
FetchError: Cannot fetch http://cekirdek.uludag.org.tr/~eray/hello-1.3.tar.gz; nodename nor servname provided, or not known

----------------------------------------------------------------------
Ran 2 tests in 0.007s

FAILED (errors=2)
testFileInfo (filestests.FilesTestCase) ... ok

----------------------------------------------------------------------
Ran 1 test in 0.001s

OK
testLocalFile (filetests.FileTestCase) ... ok
testRemoteRead (filetests.FileTestCase) ... ERROR

======================================================================
ERROR: testRemoteRead (filetests.FileTestCase)
----------------------------------------------------------------------
Traceback (most recent call last):
  File "/Volumes/Centauri/Users/malfunct/Code/projects/pisi/tests/filetests.py", line 30, in testRemoteRead
    f = File("http://uludag.org.tr/haberler/rootfs0.2.html", File.read)
  File "./pisi/file.py", line 160, in __init__
    localfile = File.download(uri, transfer_dir, sha1sum, compress, sign)
  File "./pisi/file.py", line 119, in download
    fetch_url(uri, transfer_dir, ctx.ui.Progress)
  File "./pisi/fetcher.py", line 55, in fetch_url
    fetch.fetch()
  File "./pisi/fetcher.py", line 100, in fetch
    self.fetchRemoteFile(partial_file)
  File "./pisi/fetcher.py", line 198, in fetchRemoteFile
    self.err(_('Cannot fetch %s; %s') % (uri, e[-1][-1]))
  File "./pisi/fetcher.py", line 253, in err
    raise FetchError(error)
FetchError: Cannot fetch http://uludag.org.tr/haberler/rootfs0.2.html; nodename nor servname provided, or not known

----------------------------------------------------------------------
Ran 2 tests in 0.129s

FAILED (errors=1)
testCycle (graphtests.GraphTestCase) ... ok
testTopologicalSort (graphtests.GraphTestCase) ... ok

----------------------------------------------------------------------
Ran 2 tests in 0.000s

OK
testInstall (installdbtests.InstallDBTestCase) ... ok
testRemoveDummy (installdbtests.InstallDBTestCase) ... ok
testRemovePurge (installdbtests.InstallDBTestCase) ... ok

----------------------------------------------------------------------
Ran 3 tests in 2.161s

OK
testRead (metadatatests.MetaDataTestCase) ... ERROR
testVerify (metadatatests.MetaDataTestCase) ... ERROR
testWrite (metadatatests.MetaDataTestCase) ... ERROR

======================================================================
ERROR: testRead (metadatatests.MetaDataTestCase)
----------------------------------------------------------------------
Traceback (most recent call last):
  File "/Volumes/Centauri/Users/malfunct/Code/projects/pisi/tests/metadatatests.py", line 22, in testRead
    md.read('tests/popt/metadata.xml')
  File "./pisi/pxml/autoxml.py", line 430, in read
    self.decode(self.rootNode(), errs)
  File "./pisi/pxml/autoxml.py", line 346, in decode
    decode_member(self, node, errs, where)
  File "./pisi/pxml/autoxml.py", line 539, in decode
    setattr(self, name, decode_a(node, errs, where + '.' + unicode(name)))
  File "./pisi/pxml/autoxml.py", line 686, in decode
    obj.decode(node, errs, where)
  File "./pisi/pxml/autoxml.py", line 346, in decode
    decode_member(self, node, errs, where)
  File "./pisi/pxml/autoxml.py", line 539, in decode
    setattr(self, name, decode_a(node, errs, where + '.' + unicode(name)))
  File "./pisi/pxml/autoxml.py", line 632, in decode
    x = autoxml.basic_cons_map[token_type](text)
TypeError: long() argument must be a string or a number, not 'NoneType'

======================================================================
ERROR: testVerify (metadatatests.MetaDataTestCase)
----------------------------------------------------------------------
Traceback (most recent call last):
  File "/Volumes/Centauri/Users/malfunct/Code/projects/pisi/tests/metadatatests.py", line 36, in testVerify
    md = self.testRead()
  File "/Volumes/Centauri/Users/malfunct/Code/projects/pisi/tests/metadatatests.py", line 22, in testRead
    md.read('tests/popt/metadata.xml')
  File "./pisi/pxml/autoxml.py", line 430, in read
    self.decode(self.rootNode(), errs)
  File "./pisi/pxml/autoxml.py", line 346, in decode
    decode_member(self, node, errs, where)
  File "./pisi/pxml/autoxml.py", line 539, in decode
    setattr(self, name, decode_a(node, errs, where + '.' + unicode(name)))
  File "./pisi/pxml/autoxml.py", line 686, in decode
    obj.decode(node, errs, where)
  File "./pisi/pxml/autoxml.py", line 346, in decode
    decode_member(self, node, errs, where)
  File "./pisi/pxml/autoxml.py", line 539, in decode
    setattr(self, name, decode_a(node, errs, where + '.' + unicode(name)))
  File "./pisi/pxml/autoxml.py", line 632, in decode
    x = autoxml.basic_cons_map[token_type](text)
TypeError: long() argument must be a string or a number, not 'NoneType'

======================================================================
ERROR: testWrite (metadatatests.MetaDataTestCase)
----------------------------------------------------------------------
Traceback (most recent call last):
  File "/Volumes/Centauri/Users/malfunct/Code/projects/pisi/tests/metadatatests.py", line 32, in testWrite
    md = self.testRead()
  File "/Volumes/Centauri/Users/malfunct/Code/projects/pisi/tests/metadatatests.py", line 22, in testRead
    md.read('tests/popt/metadata.xml')
  File "./pisi/pxml/autoxml.py", line 430, in read
    self.decode(self.rootNode(), errs)
  File "./pisi/pxml/autoxml.py", line 346, in decode
    decode_member(self, node, errs, where)
  File "./pisi/pxml/autoxml.py", line 539, in decode
    setattr(self, name, decode_a(node, errs, where + '.' + unicode(name)))
  File "./pisi/pxml/autoxml.py", line 686, in decode
    obj.decode(node, errs, where)
  File "./pisi/pxml/autoxml.py", line 346, in decode
    decode_member(self, node, errs, where)
  File "./pisi/pxml/autoxml.py", line 539, in decode
    setattr(self, name, decode_a(node, errs, where + '.' + unicode(name)))
  File "./pisi/pxml/autoxml.py", line 632, in decode
    x = autoxml.basic_cons_map[token_type](text)
TypeError: long() argument must be a string or a number, not 'NoneType'

----------------------------------------------------------------------
Ran 3 tests in 0.004s

FAILED (errors=3)
testautosuper (ootests.OOTestCase) ... ok

----------------------------------------------------------------------
Ran 1 test in 0.000s

OK
testAdd (packagedbtests.PackageDBTestCase) ... 